telegram.ext.dispatcher - ERROR - An uncaught error was raised while processing the update
Traceback (most recent call last):
  File "/home/ilya/.local/lib/python3.5/site-packages/telegram/ext/dispatcher.py", line 270, in process_update
    handler.handle_update(update, self)
  File "/home/ilya/.local/lib/python3.5/site-packages/telegram/ext/commandhandler.py", line 171, in handle_update
    return self.callback(dispatcher.bot, update, **optional_args)
  File "bot.py", line 12, in greet_user
    print(1/0)
ZeroDivisionError: division by zero
telegram.ext.dispatcher - ERROR - An uncaught error was raised while processing the update
Traceback (most recent call last):
  File "/home/ilya/.local/lib/python3.5/site-packages/telegram/ext/dispatcher.py", line 270, in process_update
    handler.handle_update(update, self)
  File "/home/ilya/.local/lib/python3.5/site-packages/telegram/ext/commandhandler.py", line 171, in handle_update
    return self.callback(dispatcher.bot, update, **optional_args)
  File "bot.py", line 12, in greet_user
    print(1/0)
ZeroDivisionError: division by zero
telegram.ext.dispatcher - ERROR - An uncaught error was raised while processing the update
Traceback (most recent call last):
  File "/home/ilya/.local/lib/python3.5/site-packages/telegram/ext/dispatcher.py", line 270, in process_update
    handler.handle_update(update, self)
  File "/home/ilya/.local/lib/python3.5/site-packages/telegram/ext/commandhandler.py", line 171, in handle_update
    return self.callback(dispatcher.bot, update, **optional_args)
  File "bot.py", line 12, in greet_user
    print(1/0)
ZeroDivisionError: division by zero
telegram.ext.dispatcher - ERROR - An uncaught error was raised while processing the update
Traceback (most recent call last):
  File "/home/ilya/.local/lib/python3.5/site-packages/telegram/ext/dispatcher.py", line 270, in process_update
    handler.handle_update(update, self)
  File "/home/ilya/.local/lib/python3.5/site-packages/telegram/ext/commandhandler.py", line 171, in handle_update
    return self.callback(dispatcher.bot, update, **optional_args)
  File "bot.py", line 12, in greet_user
    print(1/0)
ZeroDivisionError: division by zero
telegram.ext.dispatcher - ERROR - An uncaught error was raised while processing the update
Traceback (most recent call last):
  File "/home/ilya/.local/lib/python3.5/site-packages/telegram/ext/dispatcher.py", line 270, in process_update
    handler.handle_update(update, self)
  File "/home/ilya/.local/lib/python3.5/site-packages/telegram/ext/commandhandler.py", line 171, in handle_update
    return self.callback(dispatcher.bot, update, **optional_args)
  File "bot.py", line 12, in greet_user
    print(1/0)
ZeroDivisionError: division by zero
telegram.ext.dispatcher - ERROR - An uncaught error was raised while processing the update
Traceback (most recent call last):
  File "/home/ilya/.local/lib/python3.5/site-packages/telegram/ext/dispatcher.py", line 270, in process_update
    handler.handle_update(update, self)
  File "/home/ilya/.local/lib/python3.5/site-packages/telegram/ext/commandhandler.py", line 171, in handle_update
    return self.callback(dispatcher.bot, update, **optional_args)
  File "bot.py", line 12, in greet_user
    print(1/0)
ZeroDivisionError: division by zero
telegram.ext.dispatcher - ERROR - An uncaught error was raised while processing the update
Traceback (most recent call last):
  File "/home/ilya/.local/lib/python3.5/site-packages/telegram/ext/dispatcher.py", line 270, in process_update
    handler.handle_update(update, self)
  File "/home/ilya/.local/lib/python3.5/site-packages/telegram/ext/commandhandler.py", line 171, in handle_update
    return self.callback(dispatcher.bot, update, **optional_args)
  File "bot.py", line 12, in greet_user
    print(1/0)
ZeroDivisionError: division by zero
telegram.ext.dispatcher - ERROR - An uncaught error was raised while processing the update
Traceback (most recent call last):
  File "/home/ilya/.local/lib/python3.5/site-packages/telegram/ext/dispatcher.py", line 270, in process_update
    handler.handle_update(update, self)
  File "/home/ilya/.local/lib/python3.5/site-packages/telegram/ext/commandhandler.py", line 171, in handle_update
    return self.callback(dispatcher.bot, update, **optional_args)
  File "bot.py", line 12, in greet_user
    print(1/0)
ZeroDivisionError: division by zero
telegram.ext.dispatcher - ERROR - An uncaught error was raised while processing the update
Traceback (most recent call last):
  File "/home/ilya/.local/lib/python3.5/site-packages/telegram/ext/dispatcher.py", line 270, in process_update
    handler.handle_update(update, self)
  File "/home/ilya/.local/lib/python3.5/site-packages/telegram/ext/commandhandler.py", line 171, in handle_update
    return self.callback(dispatcher.bot, update, **optional_args)
  File "bot.py", line 12, in greet_user
    print(1/0)
ZeroDivisionError: division by zero
telegram.ext.updater - WARNING - Exiting immediately!
telegram.ext.dispatcher - ERROR - An uncaught error was raised while processing the update
Traceback (most recent call last):
  File "/home/ilya/.local/lib/python3.5/site-packages/telegram/ext/dispatcher.py", line 270, in process_update
    handler.handle_update(update, self)
  File "/home/ilya/.local/lib/python3.5/site-packages/telegram/ext/messagehandler.py", line 169, in handle_update
    return self.callback(dispatcher.bot, update, **optional_args)
  File "bot.py", line 18, in talk_to_me
    logging.INFO(user_text)
TypeError: 'int' object is not callable
telegram.ext.dispatcher - ERROR - An uncaught error was raised while processing the update
Traceback (most recent call last):
  File "/home/ilya/.local/lib/python3.5/site-packages/telegram/ext/dispatcher.py", line 270, in process_update
    handler.handle_update(update, self)
  File "/home/ilya/.local/lib/python3.5/site-packages/telegram/ext/messagehandler.py", line 169, in handle_update
    return self.callback(dispatcher.bot, update, **optional_args)
  File "bot.py", line 18, in talk_to_me
    logging.INFO(user_text)
TypeError: 'int' object is not callable
telegram.ext.updater - WARNING - Exiting immediately!
telegram.ext.dispatcher - ERROR - An uncaught error was raised while processing the update
Traceback (most recent call last):
  File "/home/ilya/.local/lib/python3.5/site-packages/telegram/ext/dispatcher.py", line 270, in process_update
    handler.handle_update(update, self)
  File "/home/ilya/.local/lib/python3.5/site-packages/telegram/ext/messagehandler.py", line 169, in handle_update
    return self.callback(dispatcher.bot, update, **optional_args)
  File "bot.py", line 18, in talk_to_me
    logging.INFO(user_text)
TypeError: 'int' object is not callable
telegram.ext.dispatcher - ERROR - An uncaught error was raised while processing the update
Traceback (most recent call last):
  File "/home/ilya/.local/lib/python3.5/site-packages/telegram/ext/dispatcher.py", line 270, in process_update
    handler.handle_update(update, self)
  File "/home/ilya/.local/lib/python3.5/site-packages/telegram/ext/messagehandler.py", line 169, in handle_update
    return self.callback(dispatcher.bot, update, **optional_args)
  File "bot.py", line 18, in talk_to_me
    logging.INFO(user_text)
TypeError: 'int' object is not callable
telegram.ext.updater - WARNING - Exiting immediately!
root - INFO - апрп
root - INFO - апр
telegram.ext.updater - WARNING - Exiting immediately!
root - INFO - вапвапв
telegram.ext.updater - WARNING - Exiting immediately!
